<?xml version="1.0"?>
<robot name = "robot_arm">

<!-- base link -->

<link name = "base_link">
    <visual>
    <geometry>
	  <mesh filename="package://robot_description/meshes/bese_link.STL" scale="0.006 0.006 0.006"/>

        <!--cylinder length="0.1" radius="0.1"/--> 
    </geometry>
    <origin xyz="0 1.1 1.45" rpy="1.67 2.25 0.07"/>
    </visual>

    <collision>
        <geometry>
		    <mesh filename="package://robot_description/meshes/bese_link.STL" scale="0.006 0.006 0.006"/>

            <!-- <cylinder length="0.1" radius="0.1"/>  -->
        </geometry>
        <origin xyz="0 0 0" rpy="0 0 0"/>
    </collision>

    <inertial>
        <origin xyz="0 0 0" rpy="0 0 0"/>
        <mass value="1"/>
        <inertia ixx="0.001" ixy="0" ixz= "0" iyy="0.001" iyz="0" izz="0.001"/>
    </inertial>
</link>
<!-- link 1 -->
<link name = "link1">
    <visual>
    <geometry>
	  <mesh filename="package://robot_description/meshes/link.STL" scale="0.003 0.003 0.003"/>

        <!--cylinder length="0.1" radius="0.1"/--> 
    </geometry>
    <origin xyz="0.26 -0.175 0.04" rpy="0 0 1.55"/>
    </visual>

    <collision>
        <geometry>
		    <mesh filename="package://robot_description/meshes/link.STL" scale="0.003 0.003 0.003"/>

            <!-- <cylinder length="0.1" radius="0.1"/>  -->
        </geometry>
        <origin xyz="0 0 0" rpy="0 0 0"/>
    </collision>

    <inertial>
        <origin xyz="0 0 0" rpy="0 0 0"/>
        <mass value="1"/>
        <inertia ixx="0.001" ixy="0" ixz= "0" iyy="0.001" iyz="0" izz="0.001"/>
    </inertial>
</link>

<!--joint1-->
<joint name="joint2" type="prismatic">
    <parent link="base_link"/>
    <child link="link1"/>
    <origin xyz="0 0 0.1" rpy="0 0 0"/>
    <axis xyz="0 1 0 " />
    <limit lower="-0.43" upper="0.43" effort="100" velocity="1"/>
</joint>

<link name = "link2">
    <visual>
    <geometry>
	  <mesh filename="package://robot_description/meshes/link2.STL" scale="0.003 0.003 0.003"/>

        <!--cylinder length="0.1" radius="0.1"/--> 
    </geometry>
    <origin xyz="-0.0 -0.025 0.049" rpy="0 0 0"/>
    </visual>

    <collision>
        <geometry>
		    <mesh filename="package://robot_description/meshes/link2.STL" scale="0.003 0.003 0.003"/>

            <!-- <cylinder length="0.1" radius="0.1"/>  -->
        </geometry>
        <origin xyz="0 0 0" rpy="0 0 0"/>
    </collision>

    <inertial>
        <origin xyz="0 0 0" rpy="0 0 0"/>
        <mass value="1"/>
        <inertia ixx="0.001" ixy="0" ixz= "0" iyy="0.001" iyz="0" izz="0.001"/>
    </inertial>
</link>

<!--joint2-->
<joint name="joint3" type="prismatic">
    <parent link="link1"/>
    <child link="link2"/>
    <origin xyz="0 0 0.1" rpy="0 0 0"/>
    <axis xyz="1 0 0 " />
    <limit lower="-0.43" upper="0.43" effort="100" velocity="1"/>
</joint>


</robot>